/opt/conda/lib/python3.10/site-packages/pytorch_lightning/callbacks/model_checkpoint.py:653: Checkpoint directory ./lightning_logs/4c48giyo/checkpoints exists and is not empty.
[34m[1mwandb[39m[22m: [33mWARNING[39m Config item 'learning_rate' was locked by 'sweep' (ignored update).
Traceback (most recent call last):
  File "/tmp/ipykernel_26/257499765.py", line 26, in sweep_train
    trainer.fit(model, datamodule=data_module)
  File "/opt/conda/lib/python3.10/site-packages/pytorch_lightning/trainer/trainer.py", line 544, in fit
    call._call_and_handle_interrupt(
  File "/opt/conda/lib/python3.10/site-packages/pytorch_lightning/trainer/call.py", line 44, in _call_and_handle_interrupt
    return trainer_fn(*args, **kwargs)
  File "/opt/conda/lib/python3.10/site-packages/pytorch_lightning/trainer/trainer.py", line 580, in _fit_impl
    self._run(model, ckpt_path=ckpt_path)
  File "/opt/conda/lib/python3.10/site-packages/pytorch_lightning/trainer/trainer.py", line 970, in _run
    _log_hyperparams(self)
  File "/opt/conda/lib/python3.10/site-packages/pytorch_lightning/loggers/utilities.py", line 93, in _log_hyperparams
    logger.log_hyperparams(hparams_initial)
  File "/opt/conda/lib/python3.10/site-packages/lightning_utilities/core/rank_zero.py", line 43, in wrapped_fn
    return fn(*args, **kwargs)
  File "/opt/conda/lib/python3.10/site-packages/pytorch_lightning/loggers/wandb.py", line 422, in log_hyperparams
    self.experiment.config.update(params, allow_val_change=True)
  File "/opt/conda/lib/python3.10/site-packages/wandb/sdk/wandb_config.py", line 186, in update
    self._callback(data=sanitized)
  File "/opt/conda/lib/python3.10/site-packages/wandb/sdk/wandb_run.py", line 381, in wrapper_fn
    raise errors.UsageError(resolved_message)
wandb.errors.UsageError: Run (4c48giyo) is finished. The call to `_config_callback` will be ignored. Please make sure that you are using an active run.